---
date: '2022-09-19'
title: 'TIL 220919'
categories: ['TIL']
summary: 'Promise async await, iterable/ iterator, generator'
thumbnail: './js1.png'
---

> 실시간 모니터링 시스템을 만들며 정복하는 MEVN (주홍철 저)
> Promise로 래핑하고 async, await를 이용해 순차적으로 실행

```js
const a = () => {
  return new Promise((resolve, reject) => {
    setTimeout(() => {
      console.log(1)
      resolve(1)
    }, Math.random() * 100)
  })
}
const b = () => {
  return new Promise((resolve, reject) => {
    setTimeout(() => {
      console.log(2)
      resolve(2)
    }, Math.random() * 100)
  })
}
const c = () => {
  return new Promise((resolve, reject) => {
    setTimeout(() => {
      console.log(3)
      resolve(3)
    }, Math.random() * 100)
  })
}

const main = async () => {
  await a() // a() 프로미스를 반환하는 값을 기다려라.
  await b()
  await c()
}
main()
```

await는 async 안에서만 써야하고 async는 Promise의 resolved된 값을 반환한다.
async/await 사용목적

- Promise의 결괏값으로 생성된 변수들을 간단하게 표현.
- 무조건 then을 쓰는 것에서 벗어나 동기적으로 변수명을 정의하듯이 await 변수명 이라는 식으로 로직을 구현할 수 있다.
- try catch로 에러를 잡을 수 있으며 디버깅하기가 쉬워진다.

```js
const a = (c = 'minter') => {
  return new Promise((resolve, reject) => {
    // 비동기 함수로직
    throw new Error('[Big Error]')
    reject(new Error('[Big Error]'))
    reject('[Big Error]')
    setTimeout()(() => {
      resolve(`${c}\'s blog`)
    }, 1 * 1000)
  })
}
a()
  .then(ret => {
    return a(`Minter`)
  })
  .then(ret => {
    console.log(ret)
  })
  .catch(e => {
    console.log(`${e} 에러 발생!`)
  })
// Error: [Big Error] 에러 발생
```

**Promise는 이렇게 비동기함수의 불안정한 결과물을 하나의 값으로 만들어 로직을 구현할 수 있다는 장점이 있다.**
Promise는 3가지 상태를 갖는다.

- 함수 처리가 아직 완료되지 않은 pending상태, Promise를 정의했을 때 발동한다.
- 함수 처리가 완료되어 '프로미스 결과값'을 반환해주는 fulfilled 상태, resolve 메서드를 통해 발동한다.
- 함수 처리 실패가 발생했을 때의 rejected 상태, reject 메서드 또는 에러를 통해 발동한다.
  Promise 에서는 then과 catch로 에러 처리 할 수 있다.

catch로 하는 에러 처리 방법

```js
const async1 = param => {
  return new Promise((resolve, reject) => {
    resolve(param * 2)
  })
}
const async2 = param => {
  return new Promise((resolve, reject) => {
    throw 'Error'
    resolve(param * 2)
  })
}
async1(1)
  .then(async2)
  .then(result => {
    console.log(result)
    throw 'Error'
  })
  .catch(reason => {
    console.log(`이 Promise는 이 ${reason}으로 종료가 되었습니다.`)
  })
  .finally(() => {
    console.log(`이 로직은 Promise 이후에 무조건 실행되는 로직입니다.`)
  })
// 이 Promise는 이 Error으로 종료가 되었습니다.
// 이 로직은 Promise 이후에 무조건 실행되는 로직입니다.
```

then 뒤에 catch로 메서드체인을 설정하면 resolve든 reject든 모든 오류를 처리할 수 있다. 또한 finally로 메서드체이닝을 통해 fulfilled, rejected 상태와 관계없이 무조건 실행하는 코드를 만들 수도 있습니다. 위의 코드는 finally를 통해 에러와 상관없이 `이 로직은 Promise 이후에 무조건 실행되는 로직입니다.`를 출력한다.
Promise.all에 비동기함수들을 올리면 한번에 모든 함수들이 이벤트 큐에 올라가게 되고, Promise.all에 올라간 비동기함수가 끝나면 Promise.all 뒤에 있는 then 메서드가 실행되어 비동기를 한꺼번에 병렬로 처리할 수 있다.

```js
const async = (message, ret) => {
  return new Promise((resolve, reject) => {
    setTimeout(() => {
      console.log(message)
      console.log(new Date())
      resolve(ret)
    }, 2000)
  })
}

const promises = [async('비동기함수1발동', 1), async('비동기함수2발동', 2)]
Promise.all(promises).then(data => {
  console.log(data)
})
/**
 * Promise {<pending>}
 *Promise.all:4 비동기함수1발동
 *Promise.all:5 Mon Sep 19 2022 20:08:48 GMT+0900 (한국 표준시)
 *Promise.all:4 비동기함수2발동
 *Promise.all:5 Mon Sep 19 2022 20:08:48 GMT+0900 (한국 표준시)
 *Promise.all:14 (2) [1, 2]
 */
```
